Workbook

Sheet YTD
B2: R9 FAS FY23 TRAVEL
F4: FY22 TRAVEL | U4: FY23 | AJ4: FY22 vs. FY23 | AY4: FY23 TRAVEL TYPE
F5: PLANNED | K5: ACTUALS | P5: UNSPENT | U5: PLANNED | Z5: YTD ACTUALS | AE5: BALANCE
B6: OFFICE OF THE REGIONAL COMMISSIONER (RC)
B7: 9Q - 285X-09-RC20-Q0900000 | F7: 40600 | K7: =sum(K8:O11) -> 0 | P7: =F7-K7 -> 40600 | U7: 93000 | Z7: =sum(Z8:AD11) -> 45600.53 | AE7: =U7-Z7 -> 47399.47
B8: 9Q | F8: 1ST QTR | K8: 0 | U8: 1ST QTR | Z8: ='RC'!BB7 -> 7807.93
B9: 9Q1 | F9: 2ND QTR | K9: 0 | U9: 2ND QTR | Z9: ='RC'!BB8 -> 8141.7
B10: 9Q1B | F10: 3RD QTR | K10: 0 | U10: 3RD QTR | Z10: ='RC'!BB9 -> 18135.55
F11: 4TH QTR | K11: 0 | U11: 4TH QTR | Z11: ='RC'!BB10 -> 11515.35
B15: CUSTOMER & STAKEHOLDER ENGAGEMENT (CASE)
B16: 9QCA - 285X-09-SE20-Q09CA000 | F16: 147763 | K16: =SUM(K17:O20) -> 1842.8 | P16: =F16-K16 -> 145920.2 | U16: 195900 | Z16: =sum(Z17:AD20) -> 131427.21 | AE16: =U16-Z16 -> 64472.79
B17: 9QCAA | F17: 1ST QTR | K17: 16.8 | U17: 1ST QTR | Z17: =CASE!BB7+CASE!BB33+CASE!BB59+CASE!BB83 -> 18826.87
B18: 9QCA1 | F18: 2ND QTR | K18: 41.8 | U18: 2ND QTR | Z18: =CASE!BB8+CASE!BB34+CASE!BB60+CASE!BB84 -> 37762.6
B19: 9QCAA | F19: 3RD QTR | K19: 0 | U19: 3RD QTR | Z19: =CASE!BB9+CASE!BB35+CASE!BB61+CASE!BB85 -> 32645.68
B20: 9QCAB | F20: 4TH QTR | K20: 1784.2 | U20: 4TH QTR | Z20: =CASE!BB10+CASE!BB36+CASE!BB62+CASE!BB86 -> 42192.06
B21: 9QCAE
B24: ASSISTED ACQUISITION SERVICES (AAS)
B25: 9QFA -285X-09-AA20-A09FA00 | K25: =SUM(K26:O29) -> 6669.65 | P25: =F25-K25 -> -6669.65 | U25: 350000 | Z25: =sum(Z26:AD29) -> 73541.28 | AE25: =U25-Z25 -> 276458.72
B26: 9QFA | F26: 1st QTR | K26: 0 | U26: 1ST QTR | Z26: =AAS!BB7+AAS!BB24+AAS!BB39+AAS!BB62 -> 9420.4
B27: 9QFAC | F27: 2nd QTR | K27: 0 | U27: 2ND QTR | Z27: =AAS!BB8+AAS!BB25+AAS!BB40+AAS!BB63 -> 9736.1
B28: 9QFAD | F28: 3rd QTR | K28: 0 | U28: 3RD QTR | Z28: =AAS!BB9+AAS!BB26+AAS!BB41+AAS!BB64 -> 18591.97
B29: 9QFAE | F29: 4th QTR | K29: 6669.65 | U29: 4TH QTR | Z29: =AAS!BB10+AAS!BB27+AAS!BB42+AAS!BB65 -> 35792.81
B33: PERSONAL PROPERTY MANAGEMENT (PPM)
B34: (Sales) | F34: 75500 | K34: =SUM(K35:O38) -> 0 | P34: =F34-K34 -> 75500 | U34: 74300 | Z34: =sum(Z35:AD38) -> 28627.5 | AE34: =U34-Z34 -> 45672.5
B35: Q09SC000-285X-09-GS30-AF200 | F35: 1st QTR | K35: 0 | U35: 1ST QTR | Z35: =PPM!BB7 -> 1126.06
B36: 9QSCB | F36: 2nd QTR | K36: 0 | U36: 2ND QTR | Z36: =PPM!BB8 -> 8089.85
F37: 3rd QTR | K37: 0 | U37: 3RD QTR | Z37: =PPM!BB9 -> 2638.25
F38: 4th QTR | K38: 0 | U38: 4TH QTR | Z38: =PPM!BB10 -> 16773.34
B42: (U&D) | F42: 66000 | K42: =SUM(K43:O46) -> 0 | P42: =F42-K42 -> 66000 | U42: 99700 | Z42: =sum(Z43:AD46) -> 55265.33 | AE42: =U42-Z42 -> 44434.67
B43: K09Y1841-142A-09-GA23-GAF80 | F43: 1st QTR | K43: 0 | U43: 1ST QTR | Z43: =PPM!BB41 -> 2224.29
B44: 9QSCA | F44: 2nd QTR | K44: 0 | U44: 2ND QTR | Z44: =PPM!BB42 -> 15711.36
F45: 3rd QTR | K45: 0 | U45: 3RD QTR | Z45: =PPM!BB43 -> 14371.02
F46: 4th QTR | K46: 0 | U46: 4TH QTR | Z46: =PPM!BB44 -> 22958.66
B50: MISCELLANEOUS (not travel) | F50: FY22 TOTAL COUNT | K50: FY22 TOTAL ACTUALS | P50: FY22 MISC VCH CONCUR FEES | U50: FY23 TOTAL COUNT | Z50: FY23 TOTAL ACTUALS | AE50: FY23 CONCUR FEES
B51: OFFICE OF THE REGIONAL COMMISSIONER (RC) | F51: 2 | K51: 313.6 | P51: 13.6 | U51: 1 | Z51: =SUM('RC'!BB44:BF47) -> 156.8 | AE51: =6.8*U51 -> 6.8
B52: CUSTOMER & STAKEHOLDER ENGAGEMENT (CASE) | F52: 12 | K52: 2185.47 | P52: 81.6 | U52: 16 | Z52: =SUM(CASE!BB104:BF107) -> 2342.11 | AE52: =6.8*U52 -> 108.8
B53: ASSISTED ACQUISITION SERVICES (AAS) | K53: 0 | Z53: =SUM(AAS!BB82:BF85) -> 0
B54: PERSONAL PROPERTY MANAGEMENT (PPM) | K54: 0 | Z54: =SUM(PPM!BB82:BF85) -> 0

Sheet FAS
B2: FY23 ALL FAS Travel
I4: 1ST QUARTER | S4: 2ND QTR | AC4: 3RD QTR | AM4: 4TH QTR | AW4: FAS FY23 TOTAL
I5: ESTIMATE | N5: ACTUALS | S5: ESTIMATE | X5: ACTUALS | AC5: ESTIMATE | AH5: ACTUALS | AM5: ESTIMATE | AR5: ACTUALS | AW5: PLANNED | BB5: ACTUALS | BG5: BALANCE
B6: Traveler | C6: Event Title | D6: Travel Dates | F6: Location | G6: Targeted Audience | H6: Trip Type | AW6: =YTD!U7+YTD!U16+YTD!U25+YTD!U34+YTD!U42 -> 812900 | BB6: =SUM(YTD!Z7+YTD!Z16+YTD!Z25+YTD!Z34+YTD!Z42) -> 334461.85 | BG6: =AW6-BB6 -> 478438.15
B7: Stacey Franklin | C7: CASE Leadership Meet | D7: 44815 | E7: 44819 | F7: Boston, MA | G7: Leadership | H7: D03 | I7: 2038.84 | N7: 1788.63 | AW7: 1ST QTR | BB7: =SUM(N7:R264) -> 33395.11
B8: Christina Bowman | C8: Conference | D8: 44846 | E8: 44848 | F8: San Jose, CA | G8: Conference | H8: D07 | I8: 880.08 | N8: 908.59 | AW8: 2ND QTR | BB8: =SUM(X7:AB263) -> 79194.71
B9: Jacqueline Sullo | C9: AAS Directors Meeting | D9: 44851 | E9: 44854 | F9: Denver, CO | G9: Leadership | H9: D02 | I9: 1333.38 | N9: 1288.08 | AW9: 3RD QTR | BB9: =SUM(AH7:AL263) -> 85074.87
B10: Joel Fada | C10: AAS Directors Meeting | D10: 44851 | E10: 44855 | F10: Denver, CO | G10: Leadership | H10: D03 | I10: 1734.37 | N10: 1782.83 | AW10: 4TH QTR | BB10: =sum(AR7:AV264) -> 130044.12
B11: Daniel Thiel | C11: BCS Technical Eval | D11: 44858 | E11: 44860 | F11: Bonita, CA | G11: Customer | H11: D02 | I11: 1053.63 | N11: 1026.56 | BB11: =SUM(BB7:BF10) -> 327708.81
B12: Mark Reiss | C12: Local Travel Toll/Customer Visits | D12: 44853 | E12: 44867 | F12: Various | G12: Customer | H12: D04 | I12: - | N12: 31.8
B13: Diana Lynch-Maldonado | C13: BCS Technical Eval | D13: 44858 | E13: 44862 | F13: Bonita, CA | G13: Customer | H13: D02 | I13: 1396.38 | N13: 1358.46
B14: Daniel Thiel | C14: FAS R9 Leadership Meet | D14: 44872 | E14: 44875 | F14: San Diego, CA | G14: Leadership | H14: D03 | I14: 1324.22 | N14: 1263.15
B15: Christopher Slavens | C15: FAS R9 Leadership Offsite Meeting | D15: 44872 | E15: 44875 | F15: San Diego, CA | G15: Leadership | H15: D03 | I15: 1509.67 | N15: 1282.05
B16: Stacey Franklin | C16: FAS R9 Leadership Offsite Meeting | D16: 44872 | E16: 44875 | F16: San Diego, CA | G16: Leadership | H16: D03 | I16: 1559.67 | N16: 1152.1
B17: Drew Della Valle | C17: FAS R9 Leadership Offsite Meeting | D17: 44872 | E17: 44875 | F17: San Diego, CA | G17: Leadership | H17: D03 | I17: 1057.65 | N17: 1138.4
B18: Sandra Klar | C18: FAS R9 Leadership Offsite Meeting | D18: 44872 | E18: 44875 | F18: San Diego, CA | G18: Leadership | H18: D03 | I18: 1104.87 | N18: 1085.89
B19: Sindi Cheng-Nishimura | C19: FAS R9 Leadership Offsite Meeting | D19: 44872 | E19: 44875 | F19: San Diego, CA | G19: Leadership | H19: D03 | I19: 1076.33 | N19: 1126.06
B20: Charles Lee | C20: FAS R9 Leadership Meeting | D20: 44872 | E20: 44875 | F20: San Diego, CA | G20: Leadership | H20: D03 | I20: 995.12 | N20: 893.93
B21: Elizabeth Belenis | C21: FAS R9 Leadership Meeting | D21: 44872 | E21: 44875 | F21: San Diego, CA | G21: Leadership | H21: D03 | I21: 1091.87 | N21: 1074.75
B22: Jacqueline Sullo | C22: FAS R9 Leadership Offsite Meeting | D22: 44872 | E22: 44875 | F22: San Diego, CA | G22: Leadership | H22: D03 | I22: 1063.57 | N22: 1023.96
B23: Joel Fada | C23: FAS R9 Leadership Offsite Meeting | D23: 44872 | E23: 44875 | F23: San Diego, CA | G23: Leadership | H23: D03 | I23: 1532.45 | N23: 1467.47
B24: Nathan Dolezal | C24: FAS R9 Leadership Offsite Meeting | D24: 44872 | E24: 44875 | F24: San Diego, CA | G24: Leadership | H24: D03 | I24: 1291.87 | N24: 1481.54
B25: Ryan Hagan | C25: Natural Disaster Conference | D25: 44873 | E25: 44875 | F25: Anaheim, CA | G25: Customer | H25: D02 | I25: 645.12 | N25: 607.5
B26: Christina Bowman | C26: Downtown SD TEB | D26: 44858 | E26: 44862 | F26: San Diego, CA | G26: Customer | H26: D04 | I26: - | N26: 131.8
B27: Clint Steele | C27: Natural Disaster Conference _Parking | D27: 44874 | E27: 44880 | F27: Anaheim, CA | G27: Customer | H27: D04 | I27: - | N27: 46.8
B28: Andrew Nguyen | C28: GOV Parking _ SID conference | D28: 44884 | E28: 44885 | F28: Los Angeles, CA | G28: Customer | H28: D04 | I28: - | N28: 39.8
B29: William Villarroel | C29: FAS R9 Leadership Offsite Meeting | D29: 44872 | E29: 44875 | F29: San Diego, CA | G29: Leadership | H29: D03 | I29: 1116.88 | N29: 1109.87
B30: Michelle Stansberry | C30: Customer Visit | D30: 44886 | E30: 44887 | F30: Las Vegas, NV | G30: Customer | H30: D02 | I30: 268.62 | N30: 235.62
B31: Michelle Stansberry | C31: Customer Visit | D31: 44886 | E31: 44895 | F31: Las Vegas, NV | G31: Customer | H31: D02 | I31: 1016.37 | N31: 1114.43
B32: Maria Rodriguez | C32: Customer Visits & Training Herlong NV | D32: 44886 | E32: 44887 | F32: Reno, NV | G32: Customer | H32: D02 | I32: 1172.4 | N32: 1091.86
B33: Florence Francis | C33: CANCELED: Customer Visits | D33: 44880 | E33: 44882 | F33: Barstow, CA | G33: Customer | H33: D02 | I33: 738.95 | N33: -
B34: Casey Kelley | C34: FAS Leadership Council Meet | D34: 44900 | E34: 44904 | F34: Washington, DC | G34: Leadership | H34: D02 | I34: 2046.95 | N34: 2230.27
B35: Stacey Franklin | C35: CASE Leadership Meet | D35: 44906 | E35: 44910 | F35: Kansas City, MO | G35: Leadership | H35: D03 | I35: 1926.67 | N35: 1837.97
B36: Michele Tobin | C36: BD Offsite Meeting | D36: 44900 | E36: 44903 | F36: San Francisco, CA | G36: Staff | H36: D03 | I36: 1892.81 | N36: 1659.04
B37: William Villarroel | C37: FAS R9 COS Interviews | D37: 44916 | E37: 44917 | F37: San Diego, CA | G37: Internal Mtng | H37: D01 | I37: 594.87 | N37: 573.15
B38: Kerry Durkan | C38: BD Team Meet | D38: 44901 | E38: 44903 | F38: San Francisco, CA | G38: Staff | H38: D04 | I38: - | N38: 133.5
B39: Katina Watson | C39: BD Team Meet | D39: 44901 | E39: 44903 | F39: San Francisco, CA | G39: Staff | H39: D04 | I39: - | N39: 120.43
B40: Michele Tobin | C40: FAS R9 Leadership Offsite Meeting | D40: 44872 | E40: 44875 | F40: San Diego, CA | G40: Leadership | H40: D03 | I40: 1364.96 | N40: 1288.82
B41: Stacey Franklin | C41: CASE Leadership Offsite | D41: 44948 | E41: 44953 | F41: Denver, CO | G41: Leadership | H41: D03 | S41: 2402.53 | X41: 2423.67
B42: Jacqueline Sullo | C42: AAS Core Realignment Meeting | D42: 44943 | E42: 44946 | F42: Atlanta, GA | G42: Internal Mtng | H42: D03 | S42: 1359.13 | X42: 1559.09
...

Sheet RC
B2: FY23 RC Travel
I4: 1ST QUARTER | S4: 2ND QTR | AC4: 3RD QTR | AM4: 4TH QTR | AW4: FY 23 TOTAL
I5: ESTIMATE | N5: ACTUALS | S5: ESTIMATE | X5: ACTUALS | AC5: ESTIMATE | AH5: ACTUALS | AM5: ESTIMATE | AR5: ACTUALS | AW5: PLANNED | BB5: ACTUALS | BG5: BALANCE
B6: 9Q - 285X-09-RC20-Q0900000 | C6: Event Title | D6: Travel Dates | F6: Location | G6: Targeted Audience | H6: Trip Type | AW6: 93000 | BB6: =sum(BB7:BF42) -> 45600.53 | BG6: =AW6-BB6 -> 47399.47
B7: Casey Kelley | C7: Internal Management Meeting | D7: 44830 | E7: 44831 | F7: San Francisco, CA | G7: Internal Mtng | H7: D03 | I7: 628.62 | N7: 838.4 | BB7: =SUM(N7:R42) -> 7807.93 | BG7: 1ST QTR
B8: Jacqueline Sullo | C8: AAS Directors Meeting | D8: 44851 | E8: 44854 | F8: Denver, CO | G8: Leadership | H8: D02 | I8: 1333.38 | N8: 1288.08 | BB8: =SUM(X7:AB42) -> 8141.7 | BG8: 2ND QTR
B9: William Villarroel | C9: FAS R9 Leadership Offsite Meeting | D9: 44872 | E9: 44875 | F9: San Diego, CA | G9: Leadership | H9: D03 | I9: 1116.88 | N9: 1109.87 | BB9: =SUM(AH7:AL42) -> 18135.55 | BG9: 3RD QTR
B10: Jacqueline Sullo | C10: FAS R9 Leadership Offsite Meeting | D10: 44872 | E10: 44875 | F10: San Diego, CA | G10: Leadership | H10: D03 | I10: 1063.57 | N10: 1023.96 | BB10: =SUM(AR7:AV42) -> 11515.35 | BG10: 4TH QTR
B11: Casey Kelley | C11: FAS Leadership Council Meet | D11: 44900 | E11: 44904 | F11: Washington, DC | G11: Leadership | H11: D02 | I11: 2046.95 | N11: 2230.27
B12: Casey Kelley | C12: FAS R9 COS Interviews | D12: 44914 | E12: 44915 | F12: San Francisco, CA | G12: Internal Mtng | H12: D02 | I12: 604.37 | N12: 744.2
B13: William Villarroel | C13: FAS R9 COS Interviews | D13: 44916 | E13: 44917 | F13: San Diego, CA | G13: Internal Mtng | H13: D01 | I13: 594.87 | N13: 573.15
B14: Jacqueline Sullo | C14: AAS Core Realignment Meeting | D14: 44943 | E14: 44946 | F14: Atlanta, GA | G14: Internal Mtng | H14: D03 | S14: 1359.13 | X14: 1559.09
B15: Casey Kelley | C15: Leadership Council Meet | D15: 44978 | E15: 44981 | F15: Philadelphia, PA | G15: Leadership | H15: D03 | S15: 1433.68 | X15: 1640.99
B16: Casey Kelley | C16: QTRLY F4 Meeting | D16: 44998 | E16: 45001 | F16: Atlanta, GA | G16: Leadership | H16: D02 | S16: 1451.39 | X16: 1559.73
B17: Casey Kelley | C17: CASE Leadership/Staff Meet | D17: 45005 | E17: 45008 | F17: San Francisco, CA | G17: Leadership | H17: D03 | S17: 1629.9 | X17: 1760.93
B18: Christina Bowman | C18: CASE Leadership/Staff Meet | D18: 45005 | E18: 45008 | F18: San Francisco, CA | G18: Leadership | H18: D03 | S18: 1665.98 | X18: 1620.96
B19: Jacqueline Sullo | C19: AAS & Front Line Leader Meet | D19: 45033 | E19: 45037 | F19: Philadelphia, PA | G19: Leadership | H19: D03 | AC19: 1853.62 | AH19: 1961.38
B20: Casey Kelley | C20: Asia Trip | D20: 45026 | E20: 45038 | F20: Japan & Korea | G20: Foreign | H20: D40 | AC20: 8031.74 | AH20: 8229.14
B21: Jacqueline Sullo | C21: FAS R9 Leadership Offsite Meeting | D21: 45047 | E21: 45050 | F21: Phoenix, AZ | G21: Leadership | H21: D03 | AC21: 1057.67 | AH21: 1094.75
B22: Christina Bowman | C22: FAS R9 Leadership Offsite Meeting | D22: 45047 | E22: 45050 | F22: Phoenix, AZ | G22: Leadership | H22: D03 | AC22: 1114.39 | AH22: 1111.06
B23: William Villarroel | C23: FAS R9 Leadership Offsite Meeting | D23: 45047 | E23: 45050 | F23: Phoenix, AZ | G23: Leadership | H23: D03 | AC23: 1245.38 | AH23: 1092.65
B24: Casey Kelley | C24: FAS R9 Leadership Offsite Meeting | D24: 45047 | E24: 45051 | F24: Phoenix, AZ | G24: Leadership | H24: D03 | AC24: 1194.39 | AH24: 1109.87
B25: Casey Kelley | C25: CANCELLED: (See below) Leadership Council Meet | D25: 45089 | E25: 45093 | F25: Washington, DC | G25: Leadership | H25: D03 | AC25: 2279.61 | AH25: -
B26: Casey Kelley | C26: Leadership Council Meet | D26: 45089 | E26: 45096 | F26: Washington, DC | G26: Leadership | H26: D03 | AC26: 3349.4 | AH26: 3075.17
B27: Christina Bowman | C27: SWRMC at Naval Base Mileage | D27: 45056 | E27: 45056 | F27: San Diego, CA | G27: Customer | H27: D04 | AC27: - | AH27: 23.83
B28: Casey Kelley | C28: 2023 Government Contract Pricing Summit Mileage & Parking | D28: 45097 | E28: 45099 | F28: San Diego, CA | G28: Customer | H28: D04 | AC28: - | AH28: 260.88
B29: Christina Bowman | C29: 2023 Government Contract Pricing Summit Mileage & Parking | D29: 45097 | E29: 45099 | F29: San Diego, CA | G29: Customer | H29: D04 | AC29: - | AH29: 176.82
B30: Casey Kelley | C30: PPM Divisional Team Bldg Offsite | D30: 45152 | E30: 45154 | F30: Portland, OR | G30: Leadership | H30: D03 | AM30: 1245.25 | AR30: 1324.47
B31: Casey Kelley | C31: Senior Leadership Meeting | D31: 45159 | E31: 45163 | F31: Tacoma, WA | G31: Leadership | H31: D03 | AM31: 1289.27 | AR31: 1225.26
B32: Christina Bowman | C32: AAS, PBS, and CASE NAMs Meeting Mileage & Parking | D32: 45125 | E32: 45125 | F32: San Diego, CA | G32: Leadership | H32: D04 | AM32: - | AR32: 51.83
B33: Christina Bowman | C33: Leadership Offboarding and Transition | D33: 45195 | E33: 45196 | F33: San Francisco, CA | G33: Leadership | H33: D03 | AM33: 729.27 | AR33: 784.24
B34: Casey Kelley | C34: Leadership Offboarding and Transition | D34: 45195 | E34: 45196 | F34: San Francisco, CA | G34: Leadership | H34: D03 | AM34: 739.27 | AR34: 761.12
B35: Casey Kelley | C35: APEX 2 Offsite Events | D35: 45180 | E35: 45184 | F35: Fort Worth TX and Warner Robins GA | G35: Leadership | H35: D03 | AM35: 1402.4 | AR35: 1596.68
B36: Christina Bowman | C36: APEX 2 Offsite Events | D36: 45180 | E36: 45184 | F36: Fort Worth TX and Warner Robins GA | G36: Leadership | H36: D03 | AM36: 1721.29 | AR36: 1838.03
B37: William Villarroel | C37: CASE Leadership Meeting | D37: 45187 | E37: 45191 | F37: Honolulu, HI | G37: Leadership | H37: D03 | AM37: 2607.47 | AR37: 2657.72
B38: Diana Fiesco-Bugarini | C38: APEX 2 Offsite Events | D38: 45180 | E38: 45182 | F38: Forth Worth, TX | G38: Leadership | H38: D03 | AM38: 942.08 | AR38: 1109.44
B39: Casey Kelley | C39: FAS AAS Leadership & NAVWAR Meetings | D39: 45125 | E39: 45127 | F39: San Diego, CA | G39: Leadership | H39: D04 | AM39: - | AR39: 85.4
B40: Diana Fiesco-Bugarini | C40: 50 UNP Office Cleanout Final Walkthrough | D40: 45198 | E40: 45198 | F40: San Francisco, CA | G40: Leadership | H40: D04 | AM40: - | AR40: 81.16
B43: MISCELLANEOUS | C43: Event Title/Desc | D43: Servc/Payment Date | H43: Sub Obj Code
B44: Casey Kelley | C44: Professional Liablity Insurance 2023 | D44: 44916 | F44: N/A | G44: N/A | H44: B04 | I44: - | N44: 156.8 | AW44: MISC | BB44: =SUM(N44:R55) -> 156.8 | BG44: 1ST QTR
...

Sheet CASE
B2: FY23 CASE Travel
I4: 1ST QUARTER | S4: 2ND QTR | AC4: 3RD QTR | AM4: 4TH QTR | AW4: FY23 TOTAL
I5: ESTIMATE | N5: ACTUALS | S5: ESTIMATE | X5: ACTUALS | AC5: ESTIMATE | AH5: ACTUALS | AM5: ESTIMATE | AR5: ACTUALS | AW5: PLANNED | BB5: ACTUALS | BG5: BALANCE
B6: 9QCA & 9QCA1 | C6: Event Title | D6: Travel Dates | F6: Location | G6: Targeted Audience | H6: Trip Type | AW6: 195900 | BB6: =sum(BB7:BF86) -> 131427.21 | BG6: =AW6-BB6 -> 64472.79
B7: Stacey Franklin | C7: CASE Leadership Meet | D7: 44815 | E7: 44819 | F7: Boston, MA | G7: Leadership | H7: D03 | I7: 2038.84 | N7: 1788.63 | AW7: 9QCA | BB7: =SUM(N7:R31) -> 7980.49 | BG7: 1ST QTR
B8: Stacey Franklin | C8: FAS R9 Leadership Offsite Meeting | D8: 44872 | E8: 44875 | F8: San Diego, CA | G8: Leadership | H8: D03 | I8: 1559.67 | N8: 1152.1 | BB8: =SUM(X7:AB31) -> 11165.73 | BG8: 2ND QTR
B9: Michele Tobin | C9: FAS R9 Leadership Offsite Meeting | D9: 44872 | E9: 44875 | F9: San Diego, CA | G9: Leadership | H9: D03 | I9: 1364.96 | N9: 1288.82 | BB9: =SUM(AH7:AL31) -> 6659.72 | BG9: 3RD QTR
B10: Stacey Franklin | C10: CASE Leadership Meet | D10: 44906 | E10: 44910 | F10: Kansas City, MO | G10: Leadership | H10: D03 | I10: 1926.67 | N10: 1837.97 | BB10: =SUM(AR7:AV31) -> 15862.52 | BG10: 4TH QTR
B11: Michele Tobin | C11: BD Offsite Meeting | D11: 44900 | E11: 44903 | F11: San Francisco, CA | G11: Staff | H11: D03 | I11: 1892.81 | N11: 1659.04
B12: Kerry Durkan | C12: BD Team Meet | D12: 44901 | E12: 44903 | F12: San Francisco, CA | G12: Staff | H12: D04 | I12: - | N12: 133.5
B13: Katina Watson | C13: BD Team Meet | D13: 44901 | E13: 44903 | F13: San Francisco, CA | G13: Staff | H13: D04 | I13: - | N13: 120.43
B14: Stacey Franklin | C14: CASE Leadership Offsite | D14: 44948 | E14: 44953 | F14: Denver, CO | G14: Leadership | H14: D03 | S14: 2402.53 | X14: 2423.67
B15: Stacey Franklin | C15: Asia Pacific Senior Visit Prep | D15: 44975 | E15: 44982 | F15: Tokyo, JPN/ Seoul, KOR | G15: Foreign | H15: D40 | S15: 2915.02 | X15: 2873.77
B16: Michele Tobin | C16: Qtrly Leadership Visit | D16: 45005 | E16: 45010 | F16: San Francisco, CA | G16: Leadership | H16: D02 | S16: 2378.96 | X16: 2685.58
B17: Stacey Franklin | C17: R9 CASE Leadership Meet | D17: 45004 | E17: 45009 | F17: San Francisco, CA | G17: Leadership | H17: D03 | S17: 3286.17 | X17: 3130.33
B18: Kerry Durkan | C18: Leadership Meeting SF Mileage & Parking | D18: 45008 | E18: 45008 | F18: San Francisco, CA | G18: Leadership | H18: D04 | S18: - | X18: 52.38
B19: Stacey Franklin | C19: CASE Off Site Business Meet | D19: 45032 | E19: 45036 | F19: Annapolis, MD | G19: Leadership | H19: D03 | AC19: 2284.27 | AH19: 2175.83
B20: Michele Tobin | C20: CASE Off Site Business Meet | D20: 45033 | E20: 45038 | F20: Annapolis, MD | G20: Leadership | H20: D03 | AC20: 1214.68 | AH20: 1288.45
B21: Stacey Franklin | C21: R9 Leadership Offsite Meeting | D21: 45046 | E21: 45051 | F21: Phoenix, AZ | G21: Leadership | H21: D03 | AC21: 1843.11 | AH21: 1843.11
B22: Stacey Franklin | C22: CASE Meeting | D22: 45050 | E22: 45051 | F22: Phoenix, AZ | G22: Leadership | H22: D02 | AC22: 267.22 | AH22: 267.22
B23: Michele Tobin | C23: R9 Leadership Offsite Meeting | D23: 45047 | E23: 45051 | F23: Phoenix, AZ | G23: Leadership | H23: D03 | AC23: 1261.38 | AH23: 1085.11
B24: Michele Tobin | C24: BD Development OffSite Meet | D24: 45138 | E24: 45143 | F24: Oakland, CA | G24: Staff | H24: D03 | AM24: 1700.77 | AR24: 1639
B25: Stacey Franklin | C25: Asia Pacific Senior Visit Prep | D25: 45122 | E25: 45136 | F25: Japan & Korea | G25: Customer | H25: D40 | AM25: 7216.31 | AR25: 7897.78
B26: Michele Tobin | C26: BIG Conference | D26: 45165 | E26: 45172 | F26: Prince George's County MD | G26: Conference | H26: D05 | AM26: 2000.37 | AR26: 1936.08
B27: Stacey Franklin | C27: FAS Commissioner/Leadership Meeting | D27: 45173 | E27: 45176 | F27: Washington, DC | G27: Leadership | H27: D03 | AM27: 1898.07 | AR27: 1818.39
B28: Michele Tobin | C28: Offsite Leadership Meeting | D28: 45187 | E28: 45195 | F28: Honolulu, HI | G28: Leadership | H28: D03 | AM28: 2239.47 | AR28: 2145.19
B29: Katina Watson | C29: BD Team Meeting/San Francisco Office Cleanout | D29: 45139 | E29: 45145 | F29: Oakland/San Francisco, CA | G29: Staff | H29: D04 | AM29: - | AR29: 147.68
B30: Kerry Durkan | C30: BD Team Meeting/San Francisco Office Cleanout | D30: 45139 | E30: 45145 | F30: Oakland/San Francisco, CA | G30: Staff | H30: D04 | AM30: - | AR30: 184.25
B31: Michele Tobin | C31: POV Mileage, Parking, Mileage & Uber | D31: 44972 | E31: 45077 | F31: Los Angeles, CA | G31: N/A | H31: D04 | AM31: - | AR31: 94.15
B32: 9QCAA | C32: Event Title | D32: Travel Dates | F32: Location | G32: Targeted Audience | H32: Trip Type
B33: Sidney Frazier | C33: Customer Visit | D33: 44815 | E33: 44820 | F33: Iwakuni, JPN | G33: Customer | H33: D02 | I33: 1844.79 | N33: 1715.33 | AW33: 9QCAA | BB33: =sum(N33:R57) -> 4963.51 | BG33: 1ST QTR
B34: Brandy Untalan | C34: Customer Visit | D34: 44859 | E34: 44863 | F34: Saipan, MP | G34: Customer | H34: D02 | I34: 1836.21 | N34: 1966.13 | BB34: =SUM(X36:AB57) -> 20086.63 | BG34: 2ND QTR
B35: Christopher Slavens | C35: FAS R9 Leadership Offsite Meeting | D35: 44872 | E35: 44875 | F35: San Diego, CA | G35: Leadership | H35: D03 | I35: 1509.67 | N35: 1282.05 | BB35: =SUM(AH33:AL57) -> 17861.26 | BG35: 3RD QTR
B36: Cynthia McKeague | C36: Customer Visits | D36: 44962 | E36: 44967 | F36: IWAkuni, JPN | G36: Customer | H36: D02 | S36: 2199.42 | X36: 2000.42 | BB36: =SUM(AR33:AV57) -> 16932.88 | BG36: 4TH QTR
B37: Sid Frazier | C37: Customer Visits | D37: 2/5/23 | E37: 44965 | F37: IWAkuni, JPN | G37: Customer | H37: D02 | S37: 1019.27 | X37: 1036.8
B38: Christopher Slavens | C38: Asia Pacific Senior Visit Prep | D38: 44975 | E38: 44982 | F38: Tokyo, JPN/Seoul, KOR | G38: Foreign | H38: D40 | S38: 3372.02 | X38: 3279
B39: Brandy Untalan | C39: FY23 Shadowing Prog | D39: 44966 | E39: 44975 | F39: San Diego, CA | G39: Leadership | H39: D01 | S39: 6624.36 | X39: 6590.66
B40: Ronald Eisley | C40: Asia Pacific Senior Visit Prep | D40: 44979 | E40: 44982 | F40: Seoul, KOR | G40: Leadership | H40: D03 | S40: 1199.5 | X40: 1352.66
B41: Cynthia McKeague | C41: NAM Meeting with Leadership | D41: 45010 | E41: 45016 | F41: DC, WA | G41: Leadership | H41: D03 | S41: - | X41: -
B42: Cynthia McKeague | C42: RES 2023 Conference | D42: 45016 | E42: 45026 | F42: Las Vegas NV | G42: Conference | H42: D05 | S42: 3858.09 | X42: 3216.77
...

Sheet AAS
B2: FY23 AAS Travel
I4: 1ST QUARTER | S4: 2ND QTR | AC4: 3RD QTR | AM4: 4TH QTR | AW4: FY22 TOTAL
I5: ESTIMATE | N5: ACTUALS | S5: ESTIMATE | X5: ACTUALS | AC5: ESTIMATE | AH5: ACTUALS | AM5: ESTIMATE | AR5: ACTUALS | AW5: PLANNED | BB5: ACTUALS | BG5: BALANCE
B6: 9QFA | C6: Event Title | D6: Travel Dates | F6: Location | G6: Targeted Audience | H6: Trip Type | AW6: 350000 | BB6: =sum(BB7:BF65) -> 73541.28 | BG6: =AW6-BB6 -> 276458.72
B7: Joel Fada | C7: AAS Directors Meeting | D7: 44851 | E7: 44855 | F7: Denver, CO | G7: Leadership | H7: D03 | I7: 1734.37 | N7: 1782.83 | AW7: 9QFA | BB7: =SUM(N7:R22) -> 3250.3 | BG7: 1ST QTR
B8: Joel Fada | C8: FAS R9 Leadership Offsite Meeting | D8: 44872 | E8: 44875 | F8: San Diego, CA | G8: Leadership | H8: D03 | I8: 1532.45 | N8: 1467.47 | BB8: =SUM(X7:AB22) -> 0 | BG8: 2ND QTR
B9: Joel Fada | C9: Leadership Meeting Mileage & Parking | D9: 45048 | E9: 45049 | F9: Phoenix, AZ | G9: Leadership | H9: D04 | AC9: - | AH9: 114.68 | BB9: =SUM(AH7:AL22) -> 4650.04 | BG9: 3RD QTR
B10: Connie Mudd | C10: Leadership Meeting Mileage & Parking | D10: 45049 | E10: 45050 | F10: Phoenix, AZ | G10: Leadership | H10: D04 | AC10: - | AH10: 51.62 | BB10: =SUM(AR7:AV22) -> 10512.81 | BG10: 4TH QTR
B11: Joel Fada | C11: Government Pricing Summit Conference | D11: 45096 | E11: 45100 | F11: San Diego, CA | G11: Conference | H11: D02 | AC11: 1643.92 | AH11: 1614.12
B12: Casey Kelley | C12: F4 AAS Travel | D12: 45084 | E12: 45089 | F12: Washington, DC | G12: Leadership | H12: D03 | AC12: 1041.25 | AH12: 1203.92
B13: Jacqueline Sullo | C13: F4 AAS Travel | D13: 45084 | E13: 45086 | F13: Washington, DC | G13: Leadership | H13: D03 | AC13: 1594.97 | AH13: 1665.7
B14: Casey Kelley | C14: CANCELLED: F4 AAS Travel | D14: 45103 | E14: 45107 | F14: Washington, DC | G14: Leadership | H14: D03 | AC14: 1821.75 | AH14: -
B15: Jacqueline Sullo | C15: AAO/AAS Leadership Meet | D15: 45124 | E15: 45127 | F15: San Diego, CA | G15: Leadership | H15: D03 | AM15: 1110.47 | AR15: 1123.75
B16: Joel Fada | C16: AAO/AAS Leadership Meet | D16: 45124 | E16: 45127 | F16: San Diego, CA | G16: Leadership | H16: D03 | AM16: 1271.22 | AR16: 1252.28
B17: Jacqueline Sullo | C17: F4 AAS Travel | D17: 45131 | E17: 45135 | F17: Washington, DC | G17: Leadership | H17: D03 | AM17: 1850.62 | AR17: 2157.8
B18: Casey Kelley | C18: F4 AAS Travel | D18: 45131 | E18: 45135 | F18: Washington, DC | G18: Leadership | H18: D03 | AM18: 1886.27 | AR18: 2461.88
B19: Jacqueline Sullo | C19: F4 AAS Travel | D19: 45138 | E19: 45141 | F19: Phoenix, AZ | G19: Leadership | H19: D03 | AM19: 909.97 | AR19: 1026.17
B20: Casey Kelley | C20: AAS Core Realignment Meeting | D20: 45165 | E20: 45170 | F20: Washington, DC | G20: Leadership | H20: D03 | AM20: 2297.27 | AR20: 2391.25
B21: Joel Fada | C21: Phoenix AAS Leadership Meeting | D21: 45139 | E21: 45141 | F21: Phoenix, AZ | G21: Leadership | H21: D04 | AM21: - | AR21: 99.68
B23: 9QFAC | C23: Event Title | D23: Travel Dates | F23: Location | G23: Targeted Audience | H23: Trip Type
B24: Nathan Dolezal | C24: FAS R9 Leadership Offsite Meeting | D24: 44872 | E24: 44875 | F24: San Diego, CA | G24: Leadership | H24: D03 | I24: 1291.87 | N24: 1481.54 | AW24: 9QFAC | BB24: =SUM(N24:R37) -> 1481.54 | BG24: 1ST QTR
B25: Nathan Dolezal | C25: Alliant 2 PMR/AFCEA 2023 | D25: 44969 | E25: 44974 | F25: San Diego, CA | G25: Customer | H25: D02 | S25: 2028.32 | X25: 1707.94 | BB25: =SUM(X24:AB37) -> 2906.01 | BG25: 2ND QTR
B26: Clevester Hines | C26: AAS TDL Summit Training | D26: 44978 | E26: 44981 | F26: Jacksonville, FL | G26: Customer | H26: D02 | S26: 1137.07 | X26: 1144.59 | BB26: =SUM(AH24:AL37) -> 4253.58 | BG26: 3RD QTR
B27: Joy Wahlmann | C27: Alliant 2 PMR/AFCEA 2023 | D27: 44970 | E27: 44970 | F27: San Diego, CA | G27: Customer | H27: D04 | S27: - | X27: 53.48 | BB27: =SUM(AR24:AV37) -> 5826.73 | BG27: 4TH QTR
B28: Shontae Williams | C28: Tech Evaluation Board | D28: 45026 | E28: 45031 | F28: San Diego, CA | G28: Customer | H28: D02 | AC28: 2340.22 | AH28: 1959.12
B29: Alberto Gomez | C29: Tech Evaluation Board | D29: 45021 | E29: 45030 | F29: San Diego, CA | G29: Customer | H29: D02 | AC29: 1510.47 | AH29: 1875.08
B30: Joy Wahlmann | C30: Analytics IDIQ Eval Mileage & Parking | D30: 45027 | E30: 45030 | F30: San Diego, CA | G30: Customer | H30: D04 | AC30: - | AH30: 281.58
B31: Shontae Williams | C31: Boulder City COR Level 2 Classes Mileage | D31: 45033 | E31: 45037 | F31: Boulder City, NV | G31: Training | H31: D04 | AC31: - | AH31: 137.8
B32: Nathan Dolezal | C32: Regional AAO/AAS Leadership Meeting | D32: 45124 | E32: 45127 | F32: San Diego, CA | G32: Leadership | H32: D03 | AM32: 1423.77 | AR32: 1339.49
B33: Nathan Dolezal | C33: DHRA Client Visit | D33: 45161 | E33: 45163 | F33: Monterey, CA | G33: Customer | H33: D02 | AM33: 1230.8 | AR33: 1217.1
B34: Joy Wahlmann | C34: DHRA Client Visit | D34: 45161 | E34: 45163 | F34: Monterey, CA | G34: Customer | H34: D02 | AM34: 1193.25 | AR34: 1180.82
B35: Alberto Gomez | C35: DHRA Client Visit | D35: 45161 | E35: 45162 | F35: Monterey, CA | G35: Customer | H35: D02 | AM35: 540.3 | AR35: 559.79
B36: Brigid Cummins | C36: DHRA Client Visit | D36: 45161 | E36: 45163 | F36: Monterey, CA | G36: Customer | H36: D02 | AM36: 1536.65 | AR36: 1529.53
B38: 9QFAD | C38: Event Title | D38: Travel Dates | F38: Location | G38: Targeted Audience | H38: Trip Type
B39: Christina Bowman | C39: Conference | D39: 44846 | E39: 44848 | F39: San Jose, CA | G39: Conference | H39: D07 | I39: 880.08 | N39: 908.59 | AW39: 9QFAE | BB39: =SUM(N39:R60) -> 4688.56 | BG39: 1ST QTR
B40: Daniel Thiel | C40: BCS Technical Eval | D40: 44858 | E40: 44860 | F40: Bonita, CA | G40: Customer | H40: D02 | I40: 1053.63 | N40: 1026.56 | BB40: =SUM(X39:AB60) -> 4413.21 | BG40: 2ND QTR
B41: Diana Lynch-Maldonado | C41: BCS Technical Eval | D41: 44858 | E41: 44862 | F41: Bonita, CA | G41: Customer | H41: D02 | I41: 1396.38 | N41: 1358.46 | BB41: =SUM(AH39:AL60) -> 2547.72 | BG41: 3RD QTR
B42: Daniel Thiel | C42: FAS R9 Leadership Meet | D42: 44872 | E42: 44875 | F42: San Diego, CA | G42: Leadership | H42: D03 | I42: 1324.22 | N42: 1263.15 | BB42: =SUM(AR39:AV60) -> 10386.67 | BG42: 4TH QTR
B43: Christina Bowman | C43: Downtown SD TEB | D43: 44858 | E43: 44862 | F43: San Diego, CA | G43: Customer | H43: D04 | I43: - | N43: 131.8
B44: Pamela Ervin | C44: Customer Visit | D44: 44979 | E44: 44980 | F44: Pleasanton, CA | G44: Customer | H44: D02 | S44: 448.47 | X44: 637.73
...

Sheet PPM
B2: FY23 PPM Travel
I4: 1ST QUARTER | S4: 2ND QTR | AC4: 3RD QTR | AM4: 4TH QTR | AW4: FY 22 TOTAL
I5: ESTIMATE | N5: ACTUALS | S5: ESTIMATE | X5: ACTUALS | AC5: ESTIMATE | AH5: ACTUALS | AM5: ESTIMATE | AR5: ACTUALS | AW5: PLANNED | BB5: ACTUALS | BG5: BALANCE
B6: Q09SC000 (Sales) 9QSCB | C6: Event Title | D6: Travel Dates | F6: Location | G6: Targeted Audience | H6: Trip Type | AW6: 74300 | BB6: =sum(BB7:BF39) -> 28627.5 | BG6: =AW6-BB6 -> 45672.5
B7: Sindi Cheng-Nishimura | C7: FAS R9 Leadership Offsite Meeting | D7: 44872 | E7: 44875 | F7: San Diego, CA | G7: Leadership | H7: D03 | I7: 1076.33 | N7: 1126.06 | AW7: Q09SC000 | BB7: =SUM(N7:R39) -> 1126.06 | BG7: 1ST QTR
B8: Shirley Tarkington | C8: HAI Heli Expo 2023 | D8: 44991 | E8: 44994 | F8: Atlanta, GA | G8: Customer | H8: D02 | S8: 1391.08 | X8: 1391.08 | AW8: Sales | BB8: =SUM(X7:AB39) -> 8089.85 | BG8: 2ND QTR
B9: Sing Cheng | C9: HAI Heli Expo 2023 | D9: 44991 | E9: 44995 | F9: Atlanta, GA | G9: Customer | H9: D02 | S9: 1434.4 | X9: 1336.25 | BB9: =SUM(AH7:AL39) -> 2638.25 | BG9: 3RD QTR
B10: Zach Dean | C10: HAI Heli Expo 2023 | D10: 44991 | E10: 44993 | F10: Atlanta, GA | G10: Customer | H10: D02 | S10: 1233.95 | X10: 1264.97 | BB10: =SUM(AR7:AV39) -> 16773.34 | BG10: 4TH QTR
B11: Helen Thach | C11: Air Force Strike Board | D11: 44993 | E11: 44994 | F11: Tucson, AZ | G11: Customer | H11: D02 | S11: 1204.67 | X11: 1132.9
B12: Christian Patterson | C12: Air Force Strike Board | D12: 44993 | E12: 44994 | F12: Tucson, AZ | G12: Customer | H12: D02 | S12: 1019.75 | X12: 931.12
B13: Sindi Cheng-Nishimura | C13: Air Force Strike Board | D13: 44993 | E13: 44994 | F13: Tucson, AZ | G13: Customer | H13: D02 | S13: 802.11 | X13: 768.56
B14: Zach Dean | C14: Heli-Expo | D14: 44991 | E14: 44993 | F14: Atlanta, GA | G14: Customer | H14: D02 | S14: 1233.95 | X14: 1264.97
B15: Sindi Cheng-Nishimura | C15: FAS R9 Leadership Offsite Meeting | D15: 45047 | E15: 45050 | F15: Phoenix, AZ | G15: Leadership | H15: D03 | AC15: 1060.38 | AH15: 1144.41
B16: Zach Dean | C16: Inteagency Committee for Aviation Policy | D16: 45062 | E16: 45064 | F16: Alexandria, VA | G16: Customer | H16: D02 | AC16: 1438.38 | AH16: 1493.84
B17: Morgan Tharpe | C17: PRZ PPM Offsite | D17: 45152 | E17: 45156 | F17: Portland, OR | G17: Staff | H17: D03 | AM17: 1767.67 | AR17: 1599.97
B18: Jonathan Chan | C18: PRZ PPM Offsite | D18: 45152 | E18: 45156 | F18: Portland, OR | G18: Staff | H18: D03 | AM18: 1543.78 | AR18: 1515.43
B19: Aaron Hinde | C19: CANCELLED: PRZ PPM Offsite | D19: 45152 | E19: 45156 | F19: Portland, OR | G19: Staff | H19: D03 | AM19: 1405.78 | AR19: -
B20: Lawrence Ong | C20: PRZ PPM Offsite | D20: 45152 | E20: 45156 | F20: Portland, OR | G20: Staff | H20: D03 | AM20: 1505.78 | AR20: 1488.55
B21: Christian Patterson | C21: PRZ PPM Offsite | D21: 45152 | E21: 45156 | F21: Portland, OR | G21: Staff | H21: D03 | AM21: 1445 | AR21: 1345
B22: Debbie Leung | C22: PRZ PPM Offsite | D22: 45152 | E22: 45156 | F22: Portland, OR | G22: Staff | H22: D03 | AM22: 1487.53 | AR22: 1318.78
B23: Sing Cheng | C23: PRZ PPM Offsite | D23: 45152 | E23: 45156 | F23: Portland, OR | G23: Staff | H23: D03 | AM23: 1453.08 | AR23: 1338.08
B24: Helen Thach | C24: PRZ PPM Offsite | D24: 45152 | E24: 45156 | F24: Portland, OR | G24: Staff | H24: D03 | AM24: 1533.78 | AR24: 1460.78
B25: Shirley Tarkington | C25: PRZ PPM Offsite | D25: 45152 | E25: 45156 | F25: Portland, OR | G25: Staff | H25: D03 | AM25: 1443.21 | AR25: 1487.52
B26: Sindi Cheng-Nishimura | C26: PRZ PPM Offsite | D26: 45152 | E26: 45156 | F26: Portland, OR | G26: Staff | H26: D03 | AM26: 1502.48 | AR26: 1518.22
B27: Yik Wu | C27: PRZ PPM Offsite | D27: 45152 | E27: 45156 | F27: Portland, OR | G27: Staff | H27: D03 | AM27: 1435.77 | AR27: 1494.98
B28: Zach Dean | C28: PRZ PPM Offsite | D28: 45152 | E28: 45156 | F28: Portland, OR | G28: Staff | H28: D03 | AM28: 1480.77 | AR28: 1493.33
B29: Sindi Cheng-Nishimura | C29: CANCELLED: PPM Sales Refresher Training | D29: 45165 | E29: 45170 | F29: Fort Worth, TX | G29: Training | H29: D06 | AM29: 1785.77 | AR29: -
B30: Bonita Powell | C30: CANCELLED: PRZ PPM Offsite | D30: 45152 | E30: 45156 | F30: Portland, OR | G30: Staff | H30: D03 | AM30: 1278.56 | AR30: -
B31: Christian Patterson | C31: CANCELLED: PPM Sales Refresher Training | D31: 45165 | E31: 45170 | F31: Portland, OR | G31: Staff | H31: D03 | AM31: 1730.99 | AR31: -
B32: Helen Thach | C32: CANCELLED: PPM Sales Refresher Training | D32: 45165 | E32: 45170 | F32: Fort Worth, TX | G32: Training | H32: D06 | AM32: 1855.77 | AR32: -
B33: Sing Cheng | C33: CANCELLED: PPM Sales Refresher Training | D33: 45165 | E33: 45170 | F33: Fort Worth, TX | G33: Training | H33: D06 | AM33: 2289.22 | AR33: -
B34: Morgan Tharpe | C34: CANCELLED: PPM Sales Refresher Training | D34: 45165 | E34: 45170 | F34: Fort Worth, TX | G34: Training | H34: D06 | AM34: 2390.65 | AR34: -
B35: Shirley Tarkington | C35: NASA Palmdale Agency Visit | D35: 45187 | E35: 45188 | F35: Palmdale, CA | G35: Customer | H35: D02 | AM35: 545.37 | AR35: 577.53
B36: Christian Patterson | C36: NASA Mtg at 50 UNP | D36: 45160 | E36: 45160 | F36: San Francisco, CA | G36: Customer | H36: D04 | AM36: - | AR36: 47.86
B37: Yik Wu | C37: NASA Mtg at 50 UNP | D37: 45160 | E37: 45160 | F37: San Francisco, CA | G37: Customer | H37: D04 | AM37: - | AR37: 36.93
B38: Sing Cheng | C38: NASA Mtg at 50 UNP | D38: 45160 | E38: 45160 | F38: San Francisco, CA | G38: Customer | H38: D04 | AM38: - | AR38: 50.38
B40: K09Y1841 (U&D) 9QSCA | C40: Event Title | D40: Travel Dates | F40: Location | G40: Targeted Audience | H40: Trip Type | AW40: 99700 | BB40: =sum(BB41:BF44) -> 55265.33 | BG40: =AW40-BB40 -> 44434.67
B41: Drew Della Valle | C41: FAS R9 Leadership Offsite Meeting | D41: 44872 | E41: 44875 | F41: San Diego, CA | G41: Leadership | H41: D03 | I41: 1057.65 | N41: 1138.4 | AW41: K09Y1841 | BB41: =SUM(N41:R80) -> 2224.29 | BG41: 1ST QTR
B42: Sandra Klar | C42: FAS R9 Leadership Offsite Meeting | D42: 44872 | E42: 44875 | F42: San Diego, CA | G42: Leadership | H42: D03 | I42: 1104.87 | N42: 1085.89 | AW42: U&D | BB42: =SUM(X41:AB80) -> 15711.36 | BG42: 2ND QTR
B43: Stephon Jackson | C43: FCN 416 Conference (Presenter) | D43: 44949 | E43: 44953 | F43: San Diego, CA | G43: Customers | H43: D02 | S43: 2018.46 | X43: 1885.06 | BB43: =SUM(AH41:AL80) -> 14371.02 | BG43: 3RD QTR
...

Sheet Pivot Table 10
A1: Trip Type | B1: 1ST QTR | C1: 2ND QTR | D1: 3RD QTR | E1: 4TH QTR | F1: TOTAL
B2: 0 | C2: 0 | D2: 0 | E2: 0
A3: B04 | B3: 156.8 | C3: 0 | D3: 0 | E3: 0 | F3: =SUM(B3:E3) -> 156.8
A4: D01 | B4: 573.15 | C4: 6590.66 | D4: 0 | E4: 0 | F4: =SUM(B4:E4) -> 7163.81
A5: D02 | B5: 8952.78 | C5: 44382.79 | D5: 33155.63 | E5: 34983.41 | F5: =SUM(B5:E5) -> 121474.61
A6: D03 | B6: 22456.46 | C6: 18542.08 | D6: 28827.33 | E6: 70375.9 | F6: =SUM(B6:E6) -> 140201.77
A7: D04 | B7: 504.13 | C7: 309.64 | D7: 1195.49 | E7: 908.56 | F7: =SUM(B7:E7) -> 2917.82
A8: D05 | B8: 0 | C8: 3216.77 | D8: 8631.49 | E8: 8388.88 | F8: =SUM(B8:E8) -> 20237.14
A9: D06 | B9: 0 | C9: 0 | D9: 0 | E9: 0 | F9: =SUM(B9:E9) -> 0
A10: D07 | B10: 908.59 | C10: 0 | D10: 0 | E10: 0 | F10: =SUM(B10:E10) -> 908.59
A11: D40 | B11: 0 | C11: 6152.77 | D11: 13264.93 | E11: 15387.37
A12: F4G | B12: 555.93 | C12: 474.57 | D12: 999.81 | E12: 271.88
A13: L01 | B13: 0 | C13: 14.33 | D13: 0 | E13: 0
A14: Sub Obj Code | B14: 0 | C14: 0 | D14: 0 | E14: 0
A15: Trip Type | B15: 0 | C15: 0 | D15: 0 | E15: 0

Sheet RCPivot Table
F1: TOTAL
F2: =SUM(B2:E2) -> 5822.28 | G2: Mission/Oper
F3: =SUM(B3:E3) -> 30296.04 | G3: Internal GSA Meeting
F4: =SUM(B4:E4) -> 679.92

Sheet CASEPivot Tables
A1: Trip Type | B1: 1st qtr | C1: 2nd qtr | D1: 3rd qtr | E1: 4th qtr | F1: TOTAL
A2: D01 | B2: 0 | C2: 6590.66 | D2: 0 | E2: 0 | F2: =SUM(B2:E2) -> 6590.66
A3: D02 | B3: 7193.69 | C3: 9789.91 | D3: 8189.21 | E3: 8549.8 | F3: =SUM(B3:E3) -> 33722.61
A4: D03 | B4: 10977.29 | C4: 11960.11 | D4: 10789.19 | E4: 15782.33 | F4: =SUM(B4:E4) -> 49508.92
A5: D04 | B5: 372.33 | C5: 52.38 | D5: 0 | E5: 536.48 | F5: =SUM(B5:E5) -> 961.19
A6: D05 | B6: 283.56 | C6: 3216.77 | D6: 8631.49 | E6: 1936.08 | F6: =SUM(B6:E6) -> 14067.9
F7: =SUM(B7:E7) -> 0
F8: =SUM(B8:E8) -> 0

Sheet AAS Pivot Table
A1: Trip Type | B1: 1st qtr | C1: 2nd qtr | D1: 3rd qtr | E1: 4th qtr | F1: TOTAL
B2: 0 | C2: 0 | D2: 0 | E2: 0 | F2: =SUM(B2:E2) -> 0
A3: D02 | B3: 2385.02 | C3: 9520.84 | D3: 7278.44 | E3: 11590.21 | F3: =SUM(B3:E3) -> 30774.51
A4: D03 | B4: 5994.99 | C4: 0 | D4: 3587.22 | E4: 13035.01 | F4: =SUM(B4:E4) -> 22617.22
F5: =SUM(B5:E5) -> 0

Sheet PPMSales Pivot Tables
A1: Trip Type | B1: 1st qtr | C1: 2nd qtr | D1: 3rd qtr | E1: 4th qtr | F1: TOTAL
A2: D02 | B2: 0 | C2: 8089.85 | D2: 1493.84 | E2: 577.53 | F2: =SUM(B2:E2) -> 10161.22
A3: D06 | B3: 0 | C3: 0 | D3: 0 | E3: 0 | F3: =SUM(B3:E3) -> 0
A4: Grand Total | B4: 0 | C4: 8089.85 | D4: 1493.84 | E4: 577.53 | F4: =SUM(B4:E4) -> 10161.22
F5: =SUM(B5:E5) -> 0
F6: =SUM(B6:E6) -> 0
F7: =SUM(B7:E7) -> 0
F8: =SUM(B8:E8) -> 0

Sheet PPMU&D Pivot Tables
A1: Trip Type | B1: 1st qtr | C1: 2nd qtr | D1: 3rd qtr | E1: 4th qtr | F1: TOTAL
A2: D02 | B2: 0 | C2: 15669.36 | D2: 11982.27 | E2: 8859.69 | F2: =SUM(B2:E2) -> 36511.32
A3: D05 | B3: 0 | C3: 0 | D3: 0 | E3: 2391.7 | F3: =SUM(B3:E3) -> 2391.7
A4: Grand Total | B4: 0 | C4: 15669.36 | D4: 11982.27 | E4: 11251.39 | F4: =SUM(B4:E4) -> 38903.02
F5: =SUM(B5:E5) -> 0
